<?xml version="1.0"?>
<!--
  Mock robot URDF with ros2_control hardware interface description.

  This URDF defines a minimal 3-DOF robot arm with:
   - 3 revolute joints (joint_1, joint_2, joint_3)
   - Position, velocity, and effort command/state interfaces
   - MockActuatorSystem hardware plugin from rt_controller_framework

  Usage (in launch files):
    robot_description = xacro.process_file('mock_robot.urdf').toxml()
    OR read directly as XML string

  Hardware parameters:
    inertia:        Rotational inertia per joint (kg·m²)
    damping:        Viscous damping coefficient (N·m·s/rad)
    control_period: Update period in seconds (0.001 = 1kHz)
-->
<robot name="rt_mock_robot" xmlns:xacro="http://www.ros.org/wiki/xacro">

  <!-- ═══════════════════════════════════════════════════════════════════════ -->
  <!-- ros2_control Hardware Interface                                        -->
  <!-- ═══════════════════════════════════════════════════════════════════════ -->
  <ros2_control name="MockActuatorSystem" type="system">
    <hardware>
      <plugin>rt_controller_framework/MockActuatorSystem</plugin>
      <param name="inertia">1.0</param>
      <param name="damping">0.1</param>
      <param name="control_period">0.001</param>
    </hardware>

    <!-- Joint 1: Base rotation (yaw) -->
    <joint name="joint_1">
      <param name="initial_position">0.0</param>
      <command_interface name="position"/>
      <command_interface name="velocity"/>
      <command_interface name="effort"/>
      <state_interface name="position"/>
      <state_interface name="velocity"/>
      <state_interface name="effort"/>
    </joint>

    <!-- Joint 2: Shoulder pitch -->
    <joint name="joint_2">
      <param name="initial_position">0.0</param>
      <command_interface name="position"/>
      <command_interface name="velocity"/>
      <command_interface name="effort"/>
      <state_interface name="position"/>
      <state_interface name="velocity"/>
      <state_interface name="effort"/>
    </joint>

    <!-- Joint 3: Elbow pitch -->
    <joint name="joint_3">
      <param name="initial_position">0.0</param>
      <command_interface name="position"/>
      <command_interface name="velocity"/>
      <command_interface name="effort"/>
      <state_interface name="position"/>
      <state_interface name="velocity"/>
      <state_interface name="effort"/>
    </joint>
  </ros2_control>

  <!-- ═══════════════════════════════════════════════════════════════════════ -->
  <!-- Robot Model (Links & Joints)                                           -->
  <!-- ═══════════════════════════════════════════════════════════════════════ -->

  <!-- Base link -->
  <link name="base_link">
    <visual>
      <geometry><cylinder radius="0.05" length="0.02"/></geometry>
    </visual>
    <collision>
      <geometry><cylinder radius="0.05" length="0.02"/></geometry>
    </collision>
    <inertial>
      <mass value="1.0"/>
      <inertia ixx="0.001" ixy="0" ixz="0" iyy="0.001" iyz="0" izz="0.001"/>
    </inertial>
  </link>

  <!-- Link 1 -->
  <link name="link_1">
    <visual>
      <origin xyz="0 0 0.1" rpy="0 0 0"/>
      <geometry><cylinder radius="0.02" length="0.2"/></geometry>
    </visual>
    <collision>
      <origin xyz="0 0 0.1" rpy="0 0 0"/>
      <geometry><cylinder radius="0.02" length="0.2"/></geometry>
    </collision>
    <inertial>
      <mass value="0.5"/>
      <origin xyz="0 0 0.1"/>
      <inertia ixx="0.001" ixy="0" ixz="0" iyy="0.001" iyz="0" izz="0.0005"/>
    </inertial>
  </link>

  <!-- Link 2 -->
  <link name="link_2">
    <visual>
      <origin xyz="0 0 0.1" rpy="0 0 0"/>
      <geometry><cylinder radius="0.02" length="0.2"/></geometry>
    </visual>
    <collision>
      <origin xyz="0 0 0.1" rpy="0 0 0"/>
      <geometry><cylinder radius="0.02" length="0.2"/></geometry>
    </collision>
    <inertial>
      <mass value="0.5"/>
      <origin xyz="0 0 0.1"/>
      <inertia ixx="0.001" ixy="0" ixz="0" iyy="0.001" iyz="0" izz="0.0005"/>
    </inertial>
  </link>

  <!-- Link 3 (end effector) -->
  <link name="link_3">
    <visual>
      <origin xyz="0 0 0.075" rpy="0 0 0"/>
      <geometry><cylinder radius="0.015" length="0.15"/></geometry>
    </visual>
    <collision>
      <origin xyz="0 0 0.075" rpy="0 0 0"/>
      <geometry><cylinder radius="0.015" length="0.15"/></geometry>
    </collision>
    <inertial>
      <mass value="0.3"/>
      <origin xyz="0 0 0.075"/>
      <inertia ixx="0.0005" ixy="0" ixz="0" iyy="0.0005" iyz="0" izz="0.0003"/>
    </inertial>
  </link>

  <!-- Joint 1: base_link → link_1 (yaw) -->
  <joint name="joint_1" type="revolute">
    <parent link="base_link"/>
    <child link="link_1"/>
    <origin xyz="0 0 0.01" rpy="0 0 0"/>
    <axis xyz="0 0 1"/>
    <limit lower="-3.14159" upper="3.14159" velocity="6.28318" effort="100.0"/>
    <dynamics damping="0.1" friction="0.01"/>
  </joint>

  <!-- Joint 2: link_1 → link_2 (pitch) -->
  <joint name="joint_2" type="revolute">
    <parent link="link_1"/>
    <child link="link_2"/>
    <origin xyz="0 0 0.2" rpy="0 0 0"/>
    <axis xyz="0 1 0"/>
    <limit lower="-3.14159" upper="3.14159" velocity="6.28318" effort="100.0"/>
    <dynamics damping="0.1" friction="0.01"/>
  </joint>

  <!-- Joint 3: link_2 → link_3 (pitch) -->
  <joint name="joint_3" type="revolute">
    <parent link="link_2"/>
    <child link="link_3"/>
    <origin xyz="0 0 0.2" rpy="0 0 0"/>
    <axis xyz="0 1 0"/>
    <limit lower="-1.5708" upper="1.5708" velocity="3.14159" effort="50.0"/>
    <dynamics damping="0.05" friction="0.01"/>
  </joint>

</robot>
